Workbook

Sheet INSTRUÇÕES
A1: PROJETO PORTO REAL — PLANILHA DE COTAÇÃO DE MATERIAIS
A2: Residência unifamiliar em Light Steel Frame · Manaus/AM · 297.36 m² fechados · revisão R56
A4: COMO USAR
A5: 1. | B5: Envie a aba ESPECIFICAÇÕES para cada fornecedor. É ela que torna o pedido cotável: quantidade sem especificação não é cotação, é palpite.
A6: 2. | B6: Peça no mínimo CINCO propostas por família (a aba FORNECEDORES já traz os nomes pesquisados, com praça).
A7: 3. | B7: Lance o preço unitário de cada fornecedor nas colunas amarelas da aba COTAÇÃO. Só isso — o resto é calculado.
A8: 4. | B8: A planilha escolhe sozinha o menor preço, o fornecedor vencedor, o total por item, o total por família e o total da obra.
A9: 5. | B9: Confira a aba REFERÊNCIAS: ela compara o total obtido com índices públicos da praça. Orçamento fora da faixa é sinal de linha faltando, não de preço ruim.
A11: CÓDIGO DE CORES
A12: AMARELO | B12: Célula de ENTRADA — é onde você digita. Nenhuma outra célula deve ser editada.
A13: AZUL (texto) | B13: Valor digitado por você.
A14: PRETO | B14: Valor calculado por fórmula.
A15: CINZA | B15: Dado vindo do modelo do projeto (quantidade, especificação, norma). Não editar.
A17: REGRAS DE COTAÇÃO
A18: Preço sem data não é preço. | B18: Toda proposta precisa de data, validade, prazo de entrega e condição de pagamento. Registre na aba FORNECEDORES.
A19: Frete dentro do preço. | B19: Peça CIF Manaus. Em praça do Norte o frete chega a 30 % do valor final e aparecer depois inviabiliza a comparação.
A20: Três propostas é o piso legal. | B20: Lei 14.133 art. 23 usa três como parâmetro de preço de mercado; cinco é a meta desta planilha.
A21: Quantidade é do projeto. | B21: As quantidades saem do modelo paramétrico, não de estimativa. Perda de corte já está embutida onde a especificação diz.
A23: O QUE ESTA PLANILHA NÃO COBRE
B24: A aba FORA DO ESCOPO lista nove frentes que NÃO estão aqui — louças, climatização, pintura, revestimento interno, marcenaria, mão de obra de acabamento, equipamento de piscina, projetos e BDI. Esta planilha cobre os sistemas construtivos modelados. Ignorar essa aba é o erro que custa caro: orçamento erra mais por linha faltando do que por preço alto.

Sheet COTAÇÃO
A1: COTAÇÃO DE MATERIAIS — preencha apenas as colunas amarelas
A2: Quantidades geradas pelo modelo paramétrico do projeto. Preço de referência (H) é hipótese declarada, nunca base de contrato. | P2: PROGRESSO | Q2: =COUNTIF(V4:V79,"COMPLETO")&" de "&76&" itens com 5 propostas" | T2: =IF(I80=0,0,SUMIF(V4:V79,"COMPLETO",I4:I79)/I80) | U2: do custo
A3: ITEM | B3: FAMÍLIA | C3: DESCRIÇÃO | D3: UN | E3: QUANT. PROJETO | F3: PERDA % | G3: QUANT. A COMPRAR | H3: PREÇO REF. (H) | I3: TOTAL REF. (H) | J3: FORN. 1 | K3: FORN. 2 | L3: FORN. 3 | M3: FORN. 4 | N3: FORN. 5 | O3: Nº DE PROPOSTAS | P3: MENOR PREÇO | Q3: FORNECEDOR VENCEDOR | R3: PREÇO MÉDIO | S3: DISPERSÃO (máx/mín) | T3: TOTAL COTADO | U3: Δ vs REF. | V3: STATUS
A4: ACO-PERF | B4: estrutura | C4: Perfil formado a frio, barras de 6 m | D4: kg | E4: 6202.2 | F4: 0 | G4: =E4*(1+F4) | H4: 11.5 | I4: =G4*H4 | O4: =COUNT(J4:N4) | P4: =IF(O4=0,"",MIN(J4:N4)) | Q4: =IF(O4=0,"",INDEX($J$3:$N$3,MATCH(P4,J4:N4,0))) | R4: =IF(O4=0,"",AVERAGE(J4:N4)) | S4: =IF(O4<2,"",MAX(J4:N4)/P4) | T4: =IF(O4=0,"",G4*P4) | U4: =IF(OR(O4=0,I4=0),"",T4/I4-1) | V4: =IF(O4=0,"PENDENTE",IF(O4>=5,"COMPLETO","PARCIAL"))
A5: PIR-75 | B5: vedacao | C5: PIR 75 mm | D5: m2 | E5: 184.3 | F5: 0 | G5: =E5*(1+F5) | H5: 132 | I5: =G5*H5 | O5: =COUNT(J5:N5) | P5: =IF(O5=0,"",MIN(J5:N5)) | Q5: =IF(O5=0,"",INDEX($J$3:$N$3,MATCH(P5,J5:N5,0))) | R5: =IF(O5=0,"",AVERAGE(J5:N5)) | S5: =IF(O5<2,"",MAX(J5:N5)/P5) | T5: =IF(O5=0,"",G5*P5) | U5: =IF(OR(O5=0,I5=0),"",T5/I5-1) | V5: =IF(O5=0,"PENDENTE",IF(O5>=5,"COMPLETO","PARCIAL"))
A6: GESSO-12,5 | B6: vedacao | C6: Chapa de gesso 12.5 mm | D6: m2 | E6: 734.2 | F6: 0 | G6: =E6*(1+F6) | H6: 28 | I6: =G6*H6 | O6: =COUNT(J6:N6) | P6: =IF(O6=0,"",MIN(J6:N6)) | Q6: =IF(O6=0,"",INDEX($J$3:$N$3,MATCH(P6,J6:N6,0))) | R6: =IF(O6=0,"",AVERAGE(J6:N6)) | S6: =IF(O6<2,"",MAX(J6:N6)/P6) | T6: =IF(O6=0,"",G6*P6) | U6: =IF(OR(O6=0,I6=0),"",T6/I6-1) | V6: =IF(O6=0,"PENDENTE",IF(O6>=5,"COMPLETO","PARCIAL"))
A7: PLCIM-10 | B7: vedacao | C7: Placa cimenticia 10 mm | D7: m2 | E7: 237.9 | F7: 0 | G7: =E7*(1+F7) | H7: 62 | I7: =G7*H7 | O7: =COUNT(J7:N7) | P7: =IF(O7=0,"",MIN(J7:N7)) | Q7: =IF(O7=0,"",INDEX($J$3:$N$3,MATCH(P7,J7:N7,0))) | R7: =IF(O7=0,"",AVERAGE(J7:N7)) | S7: =IF(O7<2,"",MAX(J7:N7)/P7) | T7: =IF(O7=0,"",G7*P7) | U7: =IF(OR(O7=0,I7=0),"",T7/I7-1) | V7: =IF(O7=0,"PENDENTE",IF(O7>=5,"COMPLETO","PARCIAL"))
A8: LAROCHA-50 | B8: vedacao | C8: La de rocha 50 mm | D8: m2 | E8: 384.6 | F8: 0 | G8: =E8*(1+F8) | H8: 34 | I8: =G8*H8 | O8: =COUNT(J8:N8) | P8: =IF(O8=0,"",MIN(J8:N8)) | Q8: =IF(O8=0,"",INDEX($J$3:$N$3,MATCH(P8,J8:N8,0))) | R8: =IF(O8=0,"",AVERAGE(J8:N8)) | S8: =IF(O8<2,"",MAX(J8:N8)/P8) | T8: =IF(O8=0,"",G8*P8) | U8: =IF(OR(O8=0,I8=0),"",T8/I8-1) | V8: =IF(O8=0,"PENDENTE",IF(O8>=5,"COMPLETO","PARCIAL"))
A9: IMP-MANTA | B9: vedacao | C9: Impermeabilizacao de area molhada | D9: m2 | E9: 131 | F9: 0 | G9: =E9*(1+F9) | H9: 78 | I9: =G9*H9 | O9: =COUNT(J9:N9) | P9: =IF(O9=0,"",MIN(J9:N9)) | Q9: =IF(O9=0,"",INDEX($J$3:$N$3,MATCH(P9,J9:N9,0))) | R9: =IF(O9=0,"",AVERAGE(J9:N9)) | S9: =IF(O9<2,"",MAX(J9:N9)/P9) | T9: =IF(O9=0,"",G9*P9) | U9: =IF(OR(O9=0,I9=0),"",T9/I9-1) | V9: =IF(O9=0,"PENDENTE",IF(O9>=5,"COMPLETO","PARCIAL"))
A10: XPS-20 | B10: vedacao | C10: XPS (ISO strip) 20 mm | D10: m2 | E10: 237.9 | F10: 0 | G10: =E10*(1+F10) | H10: 41 | I10: =G10*H10 | O10: =COUNT(J10:N10) | P10: =IF(O10=0,"",MIN(J10:N10)) | Q10: =IF(O10=0,"",INDEX($J$3:$N$3,MATCH(P10,J10:N10,0))) | R10: =IF(O10=0,"",AVERAGE(J10:N10)) | S10: =IF(O10<2,"",MAX(J10:N10)/P10) | T10: =IF(O10=0,"",G10*P10) | U10: =IF(OR(O10=0,I10=0),"",T10/I10-1) | V10: =IF(O10=0,"PENDENTE",IF(O10>=5,"COMPLETO","PARCIAL"))
A11: OSB-18 | B11: vedacao | C11: OSB estrutural 18 mm | D11: m2 | E11: 117.4 | F11: 0 | G11: =E11*(1+F11) | H11: 58 | I11: =G11*H11 | O11: =COUNT(J11:N11) | P11: =IF(O11=0,"",MIN(J11:N11)) | Q11: =IF(O11=0,"",INDEX($J$3:$N$3,MATCH(P11,J11:N11,0))) | R11: =IF(O11=0,"",AVERAGE(J11:N11)) | S11: =IF(O11<2,"",MAX(J11:N11)/P11) | T11: =IF(O11=0,"",G11*P11) | U11: =IF(OR(O11=0,I11=0),"",T11/I11-1) | V11: =IF(O11=0,"PENDENTE",IF(O11>=5,"COMPLETO","PARCIAL"))
A12: CANT | B12: vedacao | C12: Cantoneira de canto e arremate | D12: m | E12: 1009.3 | F12: 0 | G12: =E12*(1+F12) | H12: 4.5 | I12: =G12*H12 | O12: =COUNT(J12:N12) | P12: =IF(O12=0,"",MIN(J12:N12)) | Q12: =IF(O12=0,"",INDEX($J$3:$N$3,MATCH(P12,J12:N12,0))) | R12: =IF(O12=0,"",AVERAGE(J12:N12)) | S12: =IF(O12<2,"",MAX(J12:N12)/P12) | T12: =IF(O12=0,"",G12*P12) | U12: =IF(OR(O12=0,I12=0),"",T12/I12-1) | V12: =IF(O12=0,"PENDENTE",IF(O12>=5,"COMPLETO","PARCIAL"))
A13: MASSA | B13: vedacao | C13: Massa para junta, 3 demaos | D13: m | E13: 805.3 | F13: 0 | G13: =E13*(1+F13) | H13: 2.5 | I13: =G13*H13 | O13: =COUNT(J13:N13) | P13: =IF(O13=0,"",MIN(J13:N13)) | Q13: =IF(O13=0,"",INDEX($J$3:$N$3,MATCH(P13,J13:N13,0))) | R13: =IF(O13=0,"",AVERAGE(J13:N13)) | S13: =IF(O13<2,"",MAX(J13:N13)/P13) | T13: =IF(O13=0,"",G13*P13) | U13: =IF(OR(O13=0,I13=0),"",T13/I13-1) | V13: =IF(O13=0,"PENDENTE",IF(O13>=5,"COMPLETO","PARCIAL"))
A14: LAVIDRO-48 | B14: vedacao | C14: La de vidro 48 mm | D14: m2 | E14: 74.1 | F14: 0 | G14: =E14*(1+F14) | H14: 22 | I14: =G14*H14 | O14: =COUNT(J14:N14) | P14: =IF(O14=0,"",MIN(J14:N14)) | Q14: =IF(O14=0,"",INDEX($J$3:$N$3,MATCH(P14,J14:N14,0))) | R14: =IF(O14=0,"",AVERAGE(J14:N14)) | S14: =IF(O14<2,"",MAX(J14:N14)/P14) | T14: =IF(O14=0,"",G14*P14) | U14: =IF(OR(O14=0,I14=0),"",T14/I14-1) | V14: =IF(O14=0,"PENDENTE",IF(O14>=5,"COMPLETO","PARCIAL"))
A15: GESSORU-12,5 | B15: vedacao | C15: Chapa de gesso RU 12.5 mm | D15: m2 | E15: 34.1 | F15: 0 | G15: =E15*(1+F15) | H15: 36 | I15: =G15*H15 | O15: =COUNT(J15:N15) | P15: =IF(O15=0,"",MIN(J15:N15)) | Q15: =IF(O15=0,"",INDEX($J$3:$N$3,MATCH(P15,J15:N15,0))) | R15: =IF(O15=0,"",AVERAGE(J15:N15)) | S15: =IF(O15<2,"",MAX(J15:N15)/P15) | T15: =IF(O15=0,"",G15*P15) | U15: =IF(OR(O15=0,I15=0),"",T15/I15-1) | V15: =IF(O15=0,"PENDENTE",IF(O15>=5,"COMPLETO","PARCIAL"))
... A79: MO-FAB | B79: servico | C79: Mao de obra de fabrica | D79: h | E79: 46.4 | F79: 0 | G79: =E79*(1+F79) | H79: 38 | I79: =G79*H79 | O79: =COUNT(J79:N79) | P79: =IF(O79=0,"",MIN(J79:N79)) | Q79: =IF(O79=0,"",INDEX($J$3:$N$3,MATCH(P79,J79:N79,0))) | R79: =IF(O79=0,"",AVERAGE(J79:N79)) | S79: =IF(O79<2,"",MAX(J79:N79)/P79) | T79: =IF(O79=0,"",G79*P79) | U79: =IF(OR(O79=0,I79=0),"",T79/I79-1) | V79: =IF(O79=0,"PENDENTE",IF(O79>=5,"COMPLETO","PARCIAL"))
C80: TOTAL GERAL | I80: =SUM(I4:I79) | T80: =SUM(T4:T79) | U80: =IF(T80=0,"",T80/I80-1)
C82: Itens: 76 · linhas cotáveis com especificação completa: 56 · com lacuna a esclarecer com o fornecedor: 32
C83: Passe o mouse sobre a DESCRIÇÃO para ver a especificação completa, as normas e a lacuna de cada item.

Sheet RESUMO
A1: RESUMO POR FAMÍLIA
A2: Tudo aqui é fórmula sobre a aba COTAÇÃO: lançou um preço lá, muda aqui.
A4: FAMÍLIA | B4: ITENS | C4: TOTAL REF. (H) | D4: % DO CUSTO | E4: ABC | F4: TOTAL COTADO | G4: Δ vs REF. | H4: ITENS COTADOS | I4: COBERTURA
A5: vedacao | B5: 14 | C5: =SUMIF(COTAÇÃO!$B$4:$B$79,$A5,COTAÇÃO!$I$4:$I$79) | D5: =IF($C$15=0,0,C5/$C$15) | E5: =IF(D5>=0.1,"A",IF(D5>=0.03,"B","C")) | F5: =SUMIF(COTAÇÃO!$B$4:$B$79,$A5,COTAÇÃO!$T$4:$T$79) | G5: =IF(OR(F5=0,C5=0),"",F5/C5-1) | H5: =COUNTIFS(COTAÇÃO!$B$4:$B$79,$A5,COTAÇÃO!$O$4:$O$79,">0") | I5: =IF(B5=0,0,H5/B5)
A6: esquadria | B6: 8 | C6: =SUMIF(COTAÇÃO!$B$4:$B$79,$A6,COTAÇÃO!$I$4:$I$79) | D6: =IF($C$15=0,0,C6/$C$15) | E6: =IF(D6>=0.1,"A",IF(D6>=0.03,"B","C")) | F6: =SUMIF(COTAÇÃO!$B$4:$B$79,$A6,COTAÇÃO!$T$4:$T$79) | G6: =IF(OR(F6=0,C6=0),"",F6/C6-1) | H6: =COUNTIFS(COTAÇÃO!$B$4:$B$79,$A6,COTAÇÃO!$O$4:$O$79,">0") | I6: =IF(B6=0,0,H6/B6)
A7: externo | B7: 13 | C7: =SUMIF(COTAÇÃO!$B$4:$B$79,$A7,COTAÇÃO!$I$4:$I$79) | D7: =IF($C$15=0,0,C7/$C$15) | E7: =IF(D7>=0.1,"A",IF(D7>=0.03,"B","C")) | F7: =SUMIF(COTAÇÃO!$B$4:$B$79,$A7,COTAÇÃO!$T$4:$T$79) | G7: =IF(OR(F7=0,C7=0),"",F7/C7-1) | H7: =COUNTIFS(COTAÇÃO!$B$4:$B$79,$A7,COTAÇÃO!$O$4:$O$79,">0") | I7: =IF(B7=0,0,H7/B7)
A8: fundacao | B8: 11 | C8: =SUMIF(COTAÇÃO!$B$4:$B$79,$A8,COTAÇÃO!$I$4:$I$79) | D8: =IF($C$15=0,0,C8/$C$15) | E8: =IF(D8>=0.1,"A",IF(D8>=0.03,"B","C")) | F8: =SUMIF(COTAÇÃO!$B$4:$B$79,$A8,COTAÇÃO!$T$4:$T$79) | G8: =IF(OR(F8=0,C8=0),"",F8/C8-1) | H8: =COUNTIFS(COTAÇÃO!$B$4:$B$79,$A8,COTAÇÃO!$O$4:$O$79,">0") | I8: =IF(B8=0,0,H8/B8)
A9: estrutura | B9: 1 | C9: =SUMIF(COTAÇÃO!$B$4:$B$79,$A9,COTAÇÃO!$I$4:$I$79) | D9: =IF($C$15=0,0,C9/$C$15) | E9: =IF(D9>=0.1,"A",IF(D9>=0.03,"B","C")) | F9: =SUMIF(COTAÇÃO!$B$4:$B$79,$A9,COTAÇÃO!$T$4:$T$79) | G9: =IF(OR(F9=0,C9=0),"",F9/C9-1) | H9: =COUNTIFS(COTAÇÃO!$B$4:$B$79,$A9,COTAÇÃO!$O$4:$O$79,">0") | I9: =IF(B9=0,0,H9/B9)
A10: instalacao | B10: 15 | C10: =SUMIF(COTAÇÃO!$B$4:$B$79,$A10,COTAÇÃO!$I$4:$I$79) | D10: =IF($C$15=0,0,C10/$C$15) | E10: =IF(D10>=0.1,"A",IF(D10>=0.03,"B","C")) | F10: =SUMIF(COTAÇÃO!$B$4:$B$79,$A10,COTAÇÃO!$T$4:$T$79) | G10: =IF(OR(F10=0,C10=0),"",F10/C10-1) | H10: =COUNTIFS(COTAÇÃO!$B$4:$B$79,$A10,COTAÇÃO!$O$4:$O$79,">0") | I10: =IF(B10=0,0,H10/B10)
A11: servico | B11: 2 | C11: =SUMIF(COTAÇÃO!$B$4:$B$79,$A11,COTAÇÃO!$I$4:$I$79) | D11: =IF($C$15=0,0,C11/$C$15) | E11: =IF(D11>=0.1,"A",IF(D11>=0.03,"B","C")) | F11: =SUMIF(COTAÇÃO!$B$4:$B$79,$A11,COTAÇÃO!$T$4:$T$79) | G11: =IF(OR(F11=0,C11=0),"",F11/C11-1) | H11: =COUNTIFS(COTAÇÃO!$B$4:$B$79,$A11,COTAÇÃO!$O$4:$O$79,">0") | I11: =IF(B11=0,0,H11/B11)
A12: cobertura | B12: 7 | C12: =SUMIF(COTAÇÃO!$B$4:$B$79,$A12,COTAÇÃO!$I$4:$I$79) | D12: =IF($C$15=0,0,C12/$C$15) | E12: =IF(D12>=0.1,"A",IF(D12>=0.03,"B","C")) | F12: =SUMIF(COTAÇÃO!$B$4:$B$79,$A12,COTAÇÃO!$T$4:$T$79) | G12: =IF(OR(F12=0,C12=0),"",F12/C12-1) | H12: =COUNTIFS(COTAÇÃO!$B$4:$B$79,$A12,COTAÇÃO!$O$4:$O$79,">0") | I12: =IF(B12=0,0,H12/B12)
A13: fachada | B13: 4 | C13: =SUMIF(COTAÇÃO!$B$4:$B$79,$A13,COTAÇÃO!$I$4:$I$79) | D13: =IF($C$15=0,0,C13/$C$15) | E13: =IF(D13>=0.1,"A",IF(D13>=0.03,"B","C")) | F13: =SUMIF(COTAÇÃO!$B$4:$B$79,$A13,COTAÇÃO!$T$4:$T$79) | G13: =IF(OR(F13=0,C13=0),"",F13/C13-1) | H13: =COUNTIFS(COTAÇÃO!$B$4:$B$79,$A13,COTAÇÃO!$O$4:$O$79,">0") | I13: =IF(B13=0,0,H13/B13)
A14: ligacao | B14: 1 | C14: =SUMIF(COTAÇÃO!$B$4:$B$79,$A14,COTAÇÃO!$I$4:$I$79) | D14: =IF($C$15=0,0,C14/$C$15) | E14: =IF(D14>=0.1,"A",IF(D14>=0.03,"B","C")) | F14: =SUMIF(COTAÇÃO!$B$4:$B$79,$A14,COTAÇÃO!$T$4:$T$79) | G14: =IF(OR(F14=0,C14=0),"",F14/C14-1) | H14: =COUNTIFS(COTAÇÃO!$B$4:$B$79,$A14,COTAÇÃO!$O$4:$O$79,">0") | I14: =IF(B14=0,0,H14/B14)
A15: TOTAL | B15: =SUM(B5:B14) | C15: =SUM(C5:C14) | D15: =IF(C15=0,0,SUM(D5:D14)) | F15: =SUM(F5:F14) | G15: =IF(OR(F15=0,C15=0),"",F15/C15-1) | H15: =SUM(H5:H14) | I15: =IF(B15=0,0,H15/B15)
A17: INDICADORES
A18: Área fechada do projeto (m²) | C18: 297.36 | D18: dado do modelo: soma dos ambientes fechados dos dois pavimentos
A19: Total adotado (cotado se houver; senão referência) | C19: =IF(F15=0,C15,F15) | D19: enquanto não houver proposta, a planilha trabalha com o preço (H)
A20: Serviço (mão de obra de montagem já orçada) | C20: =IF(F15=0,SUMIF($A$5:$A$14,"servico",$C$5:$C$14),SUMIF($A$5:$A$14,"servico",$F$5:$F$14))
A21: Material (total menos serviço) | C21: =C19-C20
A22: Parcela de material na obra entregue | C22: 0.6 | D22: (H) de prática corrente. É a ponte entre orçamento de insumo e índice de obra pronta — mexa aqui para testar a sensibilidade
A23: Obra entregue estimada | C23: =IF(C22=0,0,C21/C22) | D23: quanto a casa custaria pronta, incluindo o que NÃO está nesta planilha
A24: Custo desta planilha por m² | C24: =C19/C18
A25: Obra entregue estimada por m² | C25: =IF(C18=0,0,C23/C18) | D25: compare com a aba REFERÊNCIAS: tem de ficar ABAIXO do índice de obra entregue, porque o escopo daqui é menor

Sheet ESPECIFICAÇÕES
A1: ESPECIFICAÇÕES — o texto que vai ao fornecedor
A2: preco unitario por unidade indicada, em BRL, com data, validade, prazo de entrega e se o frete esta incluso. Proposta sem data nao entra na comparacao
A3: ITEM | B3: FAMÍLIA | C3: DESCRIÇÃO | D3: UN | E3: QUANTIDADE | F3: ESPECIFICAÇÃO PARA COTAÇÃO | G3: NORMAS | H3: LACUNA A ESCLARECER | I3: COTÁVEL
A4: ACO-PERF | B4: estrutura | C4: Perfil formado a frio, barras de 6 m | D4: kg | E4: 6202.2 | F4: perfil formado a frio em barra de 6.000 mm; aco ZAR 230, fy 230 MPa, fu 310 MPa; revestimento Z275; massa BRUTA, ja com a perda de corte (12.8 %) | G4: NBR 14762, NBR 15253, NBR 7008 | I4: sim
A5: PIR-75 | B5: vedacao | C5: PIR 75 mm | D5: m2 | E5: 184.3 | F5: Painel sandwich PIR; chapa 1000 x 12000 mm; espessura 75 mm | G5: NBR 16373 | I5: sim
A6: GESSO-12,5 | B6: vedacao | C6: Chapa de gesso 12.5 mm | D6: m2 | E6: 734.2 | F6: Chapa de gesso; chapa 1200 x 2400 mm; espessura 12.5 mm | G6: NBR 14715 | I6: sim
A7: PLCIM-10 | B7: vedacao | C7: Placa cimenticia 10 mm | D7: m2 | E7: 237.9 | F7: Placa cimenticia; chapa 1200 x 2400 mm; espessura 10 mm | G7: NBR 15498 | I7: sim
A8: LAROCHA-50 | B8: vedacao | C8: La de rocha 50 mm | D8: m2 | E8: 384.6 | F8: La de rocha; chapa 1200 x 25000 mm; espessura 50 mm | G8: NBR 11722 | I8: sim
A9: IMP-MANTA | B9: vedacao | C9: Impermeabilizacao de area molhada | D9: m2 | E9: 131 | F9: chapa dobrada / manta conforme descricao | G9: NBR 10844, NBR 9575 | I9: sim
A10: XPS-20 | B10: vedacao | C10: XPS (ISO strip) 20 mm | D10: m2 | E10: 237.9 | F10: XPS; chapa 600 x 1250 mm; espessura 20 mm | G10: NBR 11752 | I10: sim
A11: OSB-18 | B11: vedacao | C11: OSB estrutural 18 mm | D11: m2 | E11: 117.4 | F11: OSB estrutural; chapa 1220 x 2440 mm; espessura 18 mm | G11: NBR 14810 / EN 300 | I11: sim
A12: CANT | B12: vedacao | C12: Cantoneira de canto e arremate | D12: m | E12: 1009.3 | F12: cantoneira de canto e arremate | G12: NBR 15758 | I12: sim
A13: MASSA | B13: vedacao | C13: Massa para junta, 3 demaos | D13: m | E13: 805.3 | F13: massa para junta, aplicacao em 3 demaos | G13: NBR 15758 | H13: rendimento da embalagem (metros por rolo, metros por balde): o modelo mede COMPRIMENTO de junta, nao embalagem | I13: sim
A14: LAVIDRO-48 | B14: vedacao | C14: La de vidro 48 mm | D14: m2 | E14: 74.1 | F14: La de vidro; chapa 1200 x 25000 mm; espessura 48 mm | G14: NBR 11722 | I14: sim
A15: GESSORU-12,5 | B15: vedacao | C15: Chapa de gesso RU 12.5 mm | D15: m2 | E15: 34.1 | F15: Chapa de gesso RU; chapa 1200 x 2400 mm; espessura 12.5 mm | G15: NBR 14715 | I15: sim
A16: PAR-PLA | B16: vedacao | C16: Parafuso de placa 25 mm | D16: un | E16: 9802 | F16: tipos em uso: AB 4,8x19 ponta broca, AB 5,5x25 ponta broca | G16: NBR 14762 item 8.4 | I16: sim
A17: LAVIDRO-50 | B17: vedacao | C17: La de vidro 50 mm | D17: m2 | E17: 14.9 | F17: La de vidro; chapa 1200 x 25000 mm; espessura 50 mm | G17: NBR 11722 | I17: sim
A18: FITA | B18: vedacao | C18: Fita de papel para junta | D18: m | E18: 805.3 | F18: fita de papel microperfurada para junta | G18: NBR 15758 | H18: rendimento da embalagem (metros por rolo, metros por balde): o modelo mede COMPRIMENTO de junta, nao embalagem | I18: sim
A19: COB-RUFO | B19: cobertura | C19: Rufo e contrarrufo | D19: m | E19: 160.8 | F19: chapa dobrada / manta conforme descricao | G19: NBR 10844, NBR 9575 | I19: sim
A20: COB-CALHA | B20: cobertura | C20: Calha externa 150x100 mm | D20: m | E20: 80.4 | F20: chapa dobrada / manta conforme descricao | G20: NBR 10844, NBR 9575 | I20: sim
A21: PLA-PLACA | B21: cobertura | C21: Platibanda: fechamento em placa cimenticia, duas faces | D21: m2 | E21: 71.3 | H21: o modelo nao sabe descrever este item para um fornecedor | I21: com lacuna
A22: PLA-GUIA | B22: cobertura | C22: Platibanda: guia U 92x38x0,95 | D22: m | E22: 129.6 | H22: o modelo nao sabe descrever este item para um fornecedor | I22: com lacuna
A23: COB-PAR | B23: cobertura | C23: Parafuso de fixacao do painel | D23: un | E23: 737 | F23: chapa dobrada / manta conforme descricao | G23: NBR 10844, NBR 9575 | I23: sim
A24: COB-CUME | B24: cobertura | C24: Cumeeira | D24: m | E24: 13.7 | F24: chapa dobrada / manta conforme descricao | G24: NBR 10844, NBR 9575 | I24: sim
A25: PLA-MONT | B25: cobertura | C25: Platibanda: montante Ue 90x40x12x0,95 | D25: m | E25: 60 | H25: o modelo nao sabe descrever este item para um fornecedor | I25: com lacuna
A26: ESQ-CAIX | B26: esquadria | C26: Caixilho de aluminio | D26: m | E26: 298.1 | F26: caixilho de aluminio com desempenho ENSAIADO do sistema; vidro conforme quadro, 59.64 m2 | G26: NBR 10821 | H26: classificacao de estanqueidade a agua, ao ar e a carga de vento — exige relatorio de ensaio, nunca valor | I26: sim
A27: ESQ-VIDRO | B27: esquadria | C27: Vidro (ver especificacao por vao) | D27: m2 | E27: 59.64 | F27: caixilho de aluminio com desempenho ENSAIADO do sistema; vidro conforme quadro, 59.64 m2 | G27: NBR 10821 | H27: classificacao de estanqueidade a agua, ao ar e a carga de vento — exige relatorio de ensaio, nunca valor | I27: sim
A28: FER-TRILHO | B28: esquadria | C28: Ferragem: trilho | D28: m | E28: 45.4 | F28: ferragem de esquadria conforme quadro de vaos; acabamento e sentido de abertura por vao | G28: NBR 10821 | H28: linha e fabricante da ferragem: a norma de desempenho e do SISTEMA esquadria + ferragem, e cotar ferragem solta nao garante o ensaio | I28: sim
A29: FER-BATENT | B29: esquadria | C29: Ferragem: batente | D29: un | E29: 14 | F29: ferragem de esquadria conforme quadro de vaos; acabamento e sentido de abertura por vao | G29: NBR 10821 | H29: linha e fabricante da ferragem: a norma de desempenho e do SISTEMA esquadria + ferragem, e cotar ferragem solta nao garante o ensaio | I29: sim
A30: FER-FECHO | B30: esquadria | C30: Ferragem: fecho | D30: un | E30: 56 | F30: ferragem de esquadria conforme quadro de vaos; acabamento e sentido de abertura por vao | G30: NBR 10821 | H30: linha e fabricante da ferragem: a norma de desempenho e do SISTEMA esquadria + ferragem, e cotar ferragem solta nao garante o ensaio | I30: sim
A31: FER-ROLDAN | B31: esquadria | C31: Ferragem: roldana | D31: un | E31: 116 | F31: ferragem de esquadria conforme quadro de vaos; acabamento e sentido de abertura por vao | G31: NBR 10821 | H31: linha e fabricante da ferragem: a norma de desempenho e do SISTEMA esquadria + ferragem, e cotar ferragem solta nao garante o ensaio | I31: sim
A32: FER-FECHAD | B32: esquadria | C32: Ferragem: fechadura | D32: un | E32: 14 | F32: ferragem de esquadria conforme quadro de vaos; acabamento e sentido de abertura por vao | G32: NBR 10821 | H32: linha e fabricante da ferragem: a norma de desempenho e do SISTEMA esquadria + ferragem, e cotar ferragem solta nao garante o ensaio | I32: sim
A33: FER-DOBRAD | B33: esquadria | C33: Ferragem: dobradica | D33: un | E33: 42 | F33: ferragem de esquadria conforme quadro de vaos; acabamento e sentido de abertura por vao | G33: NBR 10821 | H33: linha e fabricante da ferragem: a norma de desempenho e do SISTEMA esquadria + ferragem, e cotar ferragem solta nao garante o ensaio | I33: sim
A34: FUN-CONC | B34: fundacao | C34: Concreto fck 30 MPa | D34: m3 | E34: 37.74 | F34: fck 30 MPa, aco CA-50, tela Q196; (H) ate a sondagem: a especificacao muda com o laudo | G34: NBR 12655, NBR 6118, NBR 6122 | I34: sim
A35: FUN-ACO | B35: fundacao | C35: Aco CA-50 para radier | D35: kg | E35: 1530.2 | F35: fck 30 MPa, aco CA-50, tela Q196; (H) ate a sondagem: a especificacao muda com o laudo | G35: NBR 12655, NBR 6118, NBR 6122 | I35: sim
A36: FUN-SUBST | B36: fundacao | C36: Substituicao: areia grossa com brita graduada | D36: m3 | E36: 109.1 | F36: fck 30 MPa, aco CA-50, tela Q196; (H) ate a sondagem: a especificacao muda com o laudo | G36: NBR 12655, NBR 6118, NBR 6122 | I36: sim
A37: FUN-TELA | B37: fundacao | C37: Tela soldada Q196 | D37: m2 | E37: 410 | F37: fck 30 MPa, aco CA-50, tela Q196; (H) ate a sondagem: a especificacao muda com o laudo | G37: NBR 12655, NBR 6118, NBR 6122 | I37: sim
A38: FUN-BOTA | B38: fundacao | C38: Bota-fora do material escavado (empolado 25 %) | D38: m3 | E38: 163.6 | F38: fck 30 MPa, aco CA-50, tela Q196; (H) ate a sondagem: a especificacao muda com o laudo | G38: NBR 12655, NBR 6118, NBR 6122 | I38: sim
A39: FUN-ESCAV | B39: fundacao | C39: Escavacao do aterro superficial reprovado | D39: m3 | E39: 130.9 | F39: fck 30 MPa, aco CA-50, tela Q196; (H) ate a sondagem: a especificacao muda com o laudo | G39: NBR 12655, NBR 6118, NBR 6122 | I39: sim
A40: FUN-LASTRO | B40: fundacao | C40: Lastro de brita graduada | D40: m3 | E40: 21.8 | F40: fck 30 MPa, aco CA-50, tela Q196; (H) ate a sondagem: a especificacao muda com o laudo | G40: NBR 12655, NBR 6118, NBR 6122 | I40: sim
...

Sheet FORNECEDORES
A1: FORNECEDORES PESQUISADOS
A2: Nomes levantados por pesquisa de mercado. Preço NÃO foi coletado: loja de material não publica valor em página indexável. Complete contato, proposta e prazo ao pedir.
A3: FAMÍLIA | B3: Nº | C3: FORNECEDOR | D3: PRAÇA | E3: O QUE FORNECE | F3: CONTATO | G3: TELEFONE / E-MAIL | H3: DATA DA PROPOSTA | I3: VALIDADE | J3: PRAZO DE ENTREGA | K3: FRETE INCLUSO? | L3: CONDIÇÃO DE PAGAMENTO | M3: OBSERVAÇÃO
A4: vedacao | B4: 1 | C4: Du Norte Comercio | D4: Manaus/AM | E4: distribuidora de materiais
A5: vedacao | B5: 2 | C5: Knauf / Placo | D5: Nacional | E5: chapa de gesso, fabricante
A6: vedacao | B6: 3 | C6: Brasilit / Eternit | D6: Nacional | E6: placa cimenticia
A7: vedacao | B7: 4 | C7: Isover / Saint-Gobain | D7: Nacional | E7: la de rocha e la de vidro
A8: vedacao | B8: 5 | C8: Obramax | D8: Nacional | E8: distribuidor de construcao a seco
A9: esquadria | B9: 1 | C9: Metalurgica Aluminova | D9: Manaus/AM | E9: esquadria de aluminio e vidro temperado, 21 anos de praca
A10: esquadria | B10: 2 | C10: Esquadrias Alufynestra | D10: Manaus/AM | E10: esquadria de aluminio
A11: esquadria | B11: 3 | C11: Serralheria e Vidracaria Lopes | D11: Manaus/AM | E11: aluminio e temperado
A12: esquadria | B12: 4 | C12: Fabrica da Esquadria | D12: Nacional | E12: linha Suprema
A13: esquadria | B13: 5 | C13: Gold Esquadrias | D13: Nacional | E13: linha Suprema
A14: externo | B14: 1 | C14: Du Norte Comercio | D14: Manaus/AM | E14: bloco, areia e brita
A15: externo | B15: 2 | C15: Loja do Rei | D15: Manaus/AM | E15: bloco de concreto estrutural
... A54: ligacao | B54: 5 | C54: Distribuidores locais de ferragem | D54: Manaus/AM | E54: reposicao de obra
A56: Sem fabricante na praça de Manaus: | C56: cobertura — nao ha fabricante de painel PIR em Manaus; a cotacao tem de ser pedida CIF Manaus, com o frete DENTRO do preco e nao como surpresa na entrega

Sheet REFERÊNCIAS
A1: REFERÊNCIAS PÚBLICAS — a conferência de cima para baixo
A2: Cinco propostas dizem se o preço de cada item está bom. O índice diz se o orçamento INTEIRO está no lugar certo — e é o erro de orçamento inteiro, não o de item, que quebra obra.
A4: ÍNDICE | B4: VALOR | C4: UNIDADE | D4: DATA | E4: PRAÇA | F4: FONTE | G4: ESCOPO (o que está dentro e o que não está)
A5: CUB Amazonas, custo medio IBGE/SINAPI | B5: 1942.1 | C5: R$/m2 | D5: 2026-06 | E5: Amazonas | F5: Sinduscon-AM / compiladores de CUB | G5: materiais, mao de obra e despesas administrativas do projeto padrao; NAO inclui fundacao especial, area externa, piscina, muro, elevador, projeto nem BDI
A6: CUB Amazonas R8-N (residencial normal) | B6: 2460 | C6: R$/m2 | D6: 2026 | E6: Amazonas | F6: Sinduscon-AM | G6: idem CUB, padrao normal de acabamento
A7: Indice Steel Frame, padrao popular | B7: 3042.24 | C7: R$/m2 | D7: 2026-04 | E7: Sudeste | F7: Indice Arquitecasa Steel Frame | G7: obra entregue (chave na mao), padrao popular
A8: Indice Steel Frame, padrao medio | B8: 4543.63 | C8: R$/m2 | D8: 2026-04 | E8: Sudeste | F8: Indice Arquitecasa Steel Frame | G8: obra entregue (chave na mao), padrao medio
A9: Indice Steel Frame, padrao alto | B9: 6200.34 | C9: R$/m2 | D9: 2026-04 | E9: Sudeste | F9: Indice Arquitecasa Steel Frame | G9: obra entregue (chave na mao), padrao alto
A11: POSIÇÃO DESTE ORÇAMENTO
A12: Obra entregue estimada por m² (da aba RESUMO) | B12: =RESUMO!C25
A13: Índice steel frame, padrão popular | B13: 3042.24
A14: Índice steel frame, padrão médio | B14: 4543.63
A15: CUB Amazonas R8-N | B15: 2460
A16: Posição contra o padrão popular | B16: =IF(B12=0,"",B12/B13-1)
A17: Fator de praça (frete para o Norte) | B17: 1.2 | D17: Se os preços vierem de tabela do Sudeste, o total erra por este fator. Peça CIF Manaus e ele deixa de existir.
A19: LEITURA: o valor extrapolado TEM de ficar abaixo do índice de obra entregue, porque o escopo desta planilha é menor (ver aba FORA DO ESCOPO). Ficar ACIMA é sinal de erro — de quantidade, de preço ou de linha duplicada.

Sheet FORA DO ESCOPO
A1: O QUE NÃO ESTÁ NESTA PLANILHA
A2: Esta planilha cobre os sistemas construtivos modelados. Orçamento erra mais por LINHA FALTANDO do que por preço alto — por isso a lista existe, e por isso ela é curta e explícita.
A4: ESCOPO FORA | B4: SITUAÇÃO NO PROJETO | C4: ORÇAR SEPARADAMENTE COM
A5: loucas e metais | B5: vaso, lavatorio, cuba, torneira, registro e chuveiro estao no modelo como GEOMETRIA e nao como compra | C5: loja de material / distribuidor de louças
A6: equipamento de climatizacao | B6: as sete maquinas estao dimensionadas e locadas; o orcamento traz a linha frigorigena, nao o split | C6: instalador de ar-condicionado (7 máquinas dimensionadas em projeto)
A7: pintura | B7: PINTURA esta especificada por ambiente desde a Etapa 4; o material e a mao de obra nao entraram em linha | C7: empreiteira de pintura — material e mão de obra
A8: revestimento interno de piso e parede | B8: ACABAMENTOS define por ambiente; a compra nao foi quantificada | C8: loja de revestimento + assentador
A9: marcenaria e armarios | B9: o mobiliario existe no modelo para conferir circulacao e tomada, nao para comprar | C9: marcenaria sob medida
A10: mao de obra de instalacoes e acabamento | B10: so a montagem da estrutura esta orcada | C10: empreiteiro geral ou por frente
A11: equipamento de piscina | B11: bomba, filtro e tratamento | C11: fornecedor de piscina (bomba, filtro, tratamento)
A12: projetos complementares, ART e taxas | B12: inclui o projeto de fundacao que a pendencia 3 espera | C12: projetista estrutural com ART, prefeitura, concessionárias
A13: BDI, administracao e canteiro | B13: nao ha composicao de BDI neste modelo | C13: construtora / administração da obra
A15: PENDÊNCIAS DO PROJETO QUE AFETAM A COMPRA
A16: Nº | B16: PENDÊNCIA | C16: NORMA / ORIGEM | D16: TRAVA | E16: SITUAÇÃO
A17: 1 | B17: Certidao oficial do SU16 (CAMT, taxa de ocupacao, gabarito) | C17: Lei 1.838/2014 | D17: obra | E17: Condiciona toda a implantacao
A18: 3 | B18: Calculo estrutural do hibrido LSF + laminado, com ART | C18: NBR 8800 / 14762 | D18: fabricacao | E18: Estrutura e balanco; inclui o apoio da caixa d'agua. O pre-dimensionamento por flecha nao substitui verificacao de flambagem lateral
A19: 6 | B19: Regulamento especifico do condominio | C19: — | D19: obra | E19: Fachada, muros, recuos e especie vegetal
A20: 8 | B20: Nesting codificado dos paineis LSF | C20: fabricante | D20: fabricacao | E20: A paginacao atual e de estudo, nao de corte
A21: 12 | B21: Cotacao dos materiais: 100 % dos precos sao (H) | C21: Lei 14.133 art. 23 (parametro de 3 propostas) | D21: contrato | E21: O mapa de cotacao existe e esta pronto para sair; enquanto nao voltar, o custo e ordem de grandeza para auditar quantidade, nunca base de contrato
